<?xml version="1.0" encoding="UTF-8"?>
<testng-results skipped="0" failed="1" ignored="0" total="4" passed="3">
  <reporter-output>
  </reporter-output>
  <suite name="Default suite" duration-ms="97" started-at="2023-03-20T11:24:38Z" finished-at="2023-03-20T11:24:38Z">
    <groups>
    </groups>
    <test name="Default test" duration-ms="97" started-at="2023-03-20T11:24:38Z" finished-at="2023-03-20T11:24:38Z">
      <class name="org.test.AutomaticReRun">
        <test-method status="PASS" signature="test11()[pri:0, instance:org.test.AutomaticReRun@5ec0a365]" name="test11" duration-ms="25" started-at="2023-03-20T11:24:38Z" finished-at="2023-03-20T11:24:38Z">
          <reporter-output>
          </reporter-output>
        </test-method> <!-- test11 -->
        <test-method status="PASS" signature="test12()[pri:0, instance:org.test.AutomaticReRun@5ec0a365]" name="test12" duration-ms="2" started-at="2023-03-20T11:24:38Z" finished-at="2023-03-20T11:24:38Z">
          <reporter-output>
          </reporter-output>
        </test-method> <!-- test12 -->
        <test-method status="FAIL" signature="test13()[pri:0, instance:org.test.AutomaticReRun@5ec0a365]" name="test13" duration-ms="6" started-at="2023-03-20T11:24:38Z" finished-at="2023-03-20T11:24:38Z">
          <exception class="java.lang.AssertionError">
            <message>
              <![CDATA[expected [true] but found [false]]]>
            </message>
            <full-stacktrace>
              <![CDATA[java.lang.AssertionError: expected [true] but found [false]
at org.testng.Assert.fail(Assert.java:96)
at org.testng.Assert.failNotEquals(Assert.java:776)
at org.testng.Assert.assertTrue(Assert.java:44)
at org.testng.Assert.assertTrue(Assert.java:54)
at org.test.AutomaticReRun.test13(AutomaticReRun.java:19)
at sun.reflect.NativeMethodAccessorImpl.invoke0(Native Method)
at sun.reflect.NativeMethodAccessorImpl.invoke(Unknown Source)
at sun.reflect.DelegatingMethodAccessorImpl.invoke(Unknown Source)
at java.lang.reflect.Method.invoke(Unknown Source)
at org.testng.internal.MethodInvocationHelper.invokeMethod(MethodInvocationHelper.java:124)
at org.testng.internal.Invoker.invokeMethod(Invoker.java:583)
at org.testng.internal.Invoker.invokeTestMethod(Invoker.java:719)
at org.testng.internal.Invoker.invokeTestMethods(Invoker.java:989)
at org.testng.internal.TestMethodWorker.invokeTestMethods(TestMethodWorker.java:125)
at org.testng.internal.TestMethodWorker.run(TestMethodWorker.java:109)
at org.testng.TestRunner.privateRun(TestRunner.java:648)
at org.testng.TestRunner.run(TestRunner.java:505)
at org.testng.SuiteRunner.runTest(SuiteRunner.java:455)
at org.testng.SuiteRunner.runSequentially(SuiteRunner.java:450)
at org.testng.SuiteRunner.privateRun(SuiteRunner.java:415)
at org.testng.SuiteRunner.run(SuiteRunner.java:364)
at org.testng.SuiteRunnerWorker.runSuite(SuiteRunnerWorker.java:52)
at org.testng.SuiteRunnerWorker.run(SuiteRunnerWorker.java:84)
at org.testng.TestNG.runSuitesSequentially(TestNG.java:1208)
at org.testng.TestNG.runSuitesLocally(TestNG.java:1137)
at org.testng.TestNG.runSuites(TestNG.java:1049)
at org.testng.TestNG.run(TestNG.java:1017)
at org.testng.remote.AbstractRemoteTestNG.run(AbstractRemoteTestNG.java:114)
at org.testng.remote.RemoteTestNG.initAndRun(RemoteTestNG.java:251)
at org.testng.remote.RemoteTestNG.main(RemoteTestNG.java:77)
]]>
            </full-stacktrace>
          </exception> <!-- java.lang.AssertionError -->
          <reporter-output>
          </reporter-output>
        </test-method> <!-- test13 -->
        <test-method status="PASS" signature="test14()[pri:0, instance:org.test.AutomaticReRun@5ec0a365]" name="test14" duration-ms="2" started-at="2023-03-20T11:24:38Z" finished-at="2023-03-20T11:24:38Z">
          <reporter-output>
          </reporter-output>
        </test-method> <!-- test14 -->
      </class> <!-- org.test.AutomaticReRun -->
    </test> <!-- Default test -->
  </suite> <!-- Default suite -->
</testng-results>
